Workbook

Sheet Contas Orç
A1: CÓDIGO | B1: CONTA ANALÍTICA
A2: Conta | B2: Descricao | C2: Tipo | D2: Preview Cod. | E2: Cond. Normal | F2: Cod. Mascara | G2: Dt. Inclusao | H2: Inicio Vig. | I2: C.O.Superior
A3: 120301 | B3: IMOVEIS | C3: Sintetica | D3: 120301 | E3: Despesa | G3: 44872 | H3: 44872
A4: 120301001 | B4: TERRENOS | C4: Analitica | D4: 120301001 | E4: Despesa | G4: 44872 | H4: 44872 | I4: 120301
A5: 120301002 | B5: EDIFICIOS | C5: Analitica | D5: 120301002 | E5: Despesa | G5: 44872 | H5: 44872 | I5: 120301
A6: 120301003 | B6: INSTALACOES | C6: Analitica | D6: 120301003 | E6: Despesa | G6: 44872 | H6: 44872 | I6: 120301
A7: 120301004 | B7: TERRENOS AVP | C7: Analitica | D7: 120301004 | E7: Despesa | G7: 44872 | H7: 44872 | I7: 120301
A8: 120301005 | B8: INSTALACOES - NOVO TERMINAL | C8: Analitica | D8: 120301005 | E8: Despesa | G8: 44872 | H8: 44872 | I8: 120301
A9: 120302 | B9: MOVEIS E UTENSILIOS | C9: Sintetica | D9: 120302 | E9: Despesa | G9: 44872 | H9: 44872
A10: 120302001 | B10: MOVEIS E UTENSILIOS | C10: Analitica | D10: 120302001 | E10: Despesa | G10: 44872 | H10: 44872 | I10: 120302
A11: 120303 | B11: MAQUINAS, EQUIPAMENTOS E FERRAMENTAS | C11: Sintetica | D11: 120303 | E11: Despesa | G11: 44872 | H11: 44872
A12: 120303001 | B12: MAQUINAS E EQUIPAMENTOS | C12: Analitica | D12: 120303001 | E12: Despesa | G12: 44872 | H12: 44872 | I12: 120303
A13: 120303002 | B13: EQUIPAMENTOS DE INFORMATICA | C13: Analitica | D13: 120303002 | E13: Despesa | G13: 44872 | H13: 44872 | I13: 120303
A14: 120303003 | B14: FERRAMENTAS | C14: Analitica | D14: 120303003 | E14: Despesa | G14: 44872 | H14: 44872 | I14: 120303
A15: 120303004 | B15: MAQUINAS/EQUIPAMENTOS AVP | C15: Analitica | D15: 120303004 | E15: Despesa | G15: 44872 | H15: 44872 | I15: 120303
A16: 120304 | B16: VEICULOS | C16: Sintetica | D16: 120304 | E16: Despesa | G16: 44872 | H16: 44872
A17: 120304001 | B17: VEICULOS | C17: Analitica | D17: 120304001 | E17: Despesa | G17: 44872 | H17: 44872 | I17: 120304
A18: 120304002 | B18: CONSORCIO DE VEICULOS | C18: Analitica | D18: 120304002 | E18: Despesa | G18: 44872 | H18: 44872 | I18: 120304
A19: 120304003 | B19: VEICULOS AVP | C19: Analitica | D19: 120304003 | E19: Despesa | G19: 44872 | H19: 44872 | I19: 120304
A20: 120305 | B20: BENS ARRENDAMENTO MERCANTIL FINANCEIRO | C20: Sintetica | D20: 120305 | E20: Despesa | G20: 44872 | H20: 44872
A21: 120305001 | B21: MAQUINAS E EQUIPAMENTOS - ARRENDAMENTO | C21: Analitica | D21: 120305001 | E21: Despesa | G21: 44872 | H21: 44872 | I21: 120305
A22: 120305002 | B22: VEICULOS UTILITARIOS | C22: Analitica | D22: 120305002 | E22: Despesa | G22: 44872 | H22: 44872 | I22: 120305
A23: 120307 | B23: IMOBILIZADO EM ANDAMENTO | C23: Sintetica | D23: 120307 | E23: Despesa | G23: 44872 | H23: 44872
A24: 120307001 | B24: IMOBILIZADO EM ANDAMENTO - PROPRIOS | C24: Analitica | D24: 120307001 | E24: Despesa | G24: 44872 | H24: 44872 | I24: 120307
A25: 120307002 | B25: IMOBILIZADO EM ANDAMENTO - TERCEIROS | C25: Analitica | D25: 120307002 | E25: Despesa | G25: 44872 | H25: 44872 | I25: 120307
A26: 1204 | B26: INTANGIVEL | C26: Sintetica | D26: 1204 | E26: Despesa | G26: 44872 | H26: 44872
A27: 120401001 | B27: SOFTWARES | C27: Analitica | D27: 120401001 | E27: Despesa | G27: 44872 | H27: 44872 | I27: 1204
A28: 120402001 | B28: MARCAS E PATENTES | C28: Analitica | D28: 120402001 | E28: Despesa | G28: 44872 | H28: 44872 | I28: 1204
A29: 3101 | B29: RECEITA DE SERVICOS | C29: Sintetica | D29: 3101 | E29: Receita | G29: 44872 | H29: 44872
A30: 310101 | B30: RECEITA BRUTA DE TRANSPORTES | C30: Analitica | D30: 310101 | E30: Receita | G30: 44872 | H30: 44872 | I30: 3101
A31: 310102 | B31: RECEITA BRUTA DE OPERACOES PORTUARIAS | C31: Analitica | D31: 310102 | E31: Receita | G31: 44872 | H31: 44872 | I31: 3101
A32: 310109 | B32: ( - ) DEDUCOES DA RECEITA BRUTA | C32: Analitica | D32: 310109 | E32: Despesa | G32: 44872 | H32: 44872 | I32: 3101
A33: 3109 | B33: OUTRAS RECEITAS | C33: Sintetica | D33: 3109 | E33: Receita | G33: 44872 | H33: 44872
A34: 310901 | B34: OUTRAS RECEITAS | C34: Analitica | D34: 310901 | E34: Receita | G34: 44872 | H34: 44872 | I34: 3109
A35: 3201 | B35: CUSTOS COM PESSOAL | C35: Sintetica | D35: 3201 | E35: Despesa | G35: 44872 | H35: 44872
A36: 320101 | B36: REMUNERACOES | C36: Analitica | D36: 320101 | E36: Despesa | G36: 44872 | H36: 44872 | I36: 3201
A37: 320102 | B37: ENCARGOS SOCIAIS | C37: Analitica | D37: 320102 | E37: Despesa | G37: 44872 | H37: 44872 | I37: 3201
A38: 320103 | B38: BENEFICIOS | C38: Analitica | D38: 320103 | E38: Despesa | G38: 44872 | H38: 44872 | I38: 3201
A39: 320104 | B39: OUTROS GASTOS COM PESSOAL | C39: Analitica | D39: 320104 | E39: Despesa | G39: 44872 | H39: 44872 | I39: 3201
A40: 320105 | B40: ( - ) INSS DESONERACAO | C40: Analitica | D40: 320105 | E40: Despesa | G40: 44872 | H40: 44872 | I40: 3201
...

Sheet Base_20.12
A1: Desc_Conta | B1: CONCAT | C1: COMPETÊNCIA | D1: Valor | E1: Lote | F1: Item | G1: Data | H1: C.O. | I1: Classe | J1: Operacao | K1: Tipo | L1: Tp. Saldo | M1: Historico | N1: Unid. Medida | O1: Processo | P1: Usuario | Q1: Vlr.Lancto. | R1: Vlr.2a Moeda | S1: Vlr.3a Moeda | T1: Vlr.4a Moeda | U1: Vlr.5a Moeda | V1: Cod.Planilha | W1: Versao | X1: Centro Custo | Y1: It.Contabil | Z1: Classe Valor | AA1: Lc.Bloqueio? | AB1: Und. Orc.
A2: =IFERROR(VLOOKUP(H2,'Contas Orç'!A:B,2,0),"N/A") -> PECAS E ACESSORIOS | B2: =_xlfn.CONCAT(H2," - ",A2) -> 320301004 - PECAS E ACESSORIOS | C2: =DATE(YEAR(G2),MONTH(G2),1) -> 44866 | D2: =IF(K2="CREDITO",Q2,Q2*-1) -> 25 | E2: 0000000001 | F2: 0001 | G2: 44874 | H2: 320301004 | I2: 304 | J2: 11 | K2: Credito | L2: EM | M2: EM - PEDIDO (013491) ITEM +(0001) / (ITERRUPTOR DO NEUTRO - | O2: 000052 | P2: 000132 | Q2: 25 | R2: 0,00 | S2: 0,00 | T2: 0,00 | U2: 0,00 | V2: ORC2022 | X2: 304 | Y2: 11 | AB2: 010101
A3: =IFERROR(VLOOKUP(H3,'Contas Orç'!A:B,2,0),"N/A") -> PECAS E ACESSORIOS | B3: =_xlfn.CONCAT(H3," - ",A3) -> 330301004 - PECAS E ACESSORIOS | C3: =DATE(YEAR(G3),MONTH(G3),1) -> 44866 | D3: =IF(K3="CREDITO",Q3,Q3*-1) -> 25 | E3: 0000000001 | F3: 0002 | G3: 44874 | H3: 330301004 | I3: 201 | J3: 11 | K3: Credito | L3: EM | M3: EM - PEDIDO (013491) ITEM +(0002) / (MANCAL PARA LOCK (GUIA | O3: 000052 | P3: 000132 | Q3: 25 | R3: 0,00 | S3: 0,00 | T3: 0,00 | U3: 0,00 | V3: ORC2022 | X3: 201 | Y3: 11 | AB3: 010101
A4: =IFERROR(VLOOKUP(H4,'Contas Orç'!A:B,2,0),"N/A") -> PECAS E ACESSORIOS | B4: =_xlfn.CONCAT(H4," - ",A4) -> 320301004 - PECAS E ACESSORIOS | C4: =DATE(YEAR(G4),MONTH(G4),1) -> 44866 | D4: =IF(K4="CREDITO",Q4,Q4*-1) -> 25 | E4: 0000000002 | F4: 0001 | G4: 44874 | H4: 320301004 | I4: 304 | J4: 11 | K4: Credito | L4: RE | M4: RE - NF (909090909) P: (11150482 ) F: (000003) | O4: 000054 | P4: 000132 | Q4: 25 | R4: 0,00 | S4: 0,00 | T4: 0,00 | U4: 0,00 | X4: 304 | Y4: 11 | AB4: 010101
A5: =IFERROR(VLOOKUP(H5,'Contas Orç'!A:B,2,0),"N/A") -> PECAS E ACESSORIOS | B5: =_xlfn.CONCAT(H5," - ",A5) -> 320301004 - PECAS E ACESSORIOS | C5: =DATE(YEAR(G5),MONTH(G5),1) -> 44866 | D5: =IF(K5="CREDITO",Q5,Q5*-1) -> -25 | E5: 0000000002 | F5: 0002 | G5: 44874 | H5: 320301004 | I5: 304 | J5: 11 | K5: Debito | L5: EM | M5: EM - NF (909090909) P: (11150482 ) F: (000003) | O5: 000054 | P5: 000132 | Q5: 25 | R5: 0,00 | S5: 0,00 | T5: 0,00 | U5: 0,00 | X5: 304 | Y5: 11 | AB5: 010101
A6: =IFERROR(VLOOKUP(H6,'Contas Orç'!A:B,2,0),"N/A") -> PECAS E ACESSORIOS | B6: =_xlfn.CONCAT(H6," - ",A6) -> 330301004 - PECAS E ACESSORIOS | C6: =DATE(YEAR(G6),MONTH(G6),1) -> 44866 | D6: =IF(K6="CREDITO",Q6,Q6*-1) -> 25 | E6: 0000000002 | F6: 0003 | G6: 44874 | H6: 330301004 | I6: 201 | J6: 11 | K6: Credito | L6: RE | M6: RE - NF (909090909) P: (11010003 ) F: (000003) | O6: 000054 | P6: 000132 | Q6: 25 | R6: 0,00 | S6: 0,00 | T6: 0,00 | U6: 0,00 | X6: 201 | Y6: 11 | AB6: 010101
A7: =IFERROR(VLOOKUP(H7,'Contas Orç'!A:B,2,0),"N/A") -> PECAS E ACESSORIOS | B7: =_xlfn.CONCAT(H7," - ",A7) -> 330301004 - PECAS E ACESSORIOS | C7: =DATE(YEAR(G7),MONTH(G7),1) -> 44866 | D7: =IF(K7="CREDITO",Q7,Q7*-1) -> -25 | E7: 0000000002 | F7: 0004 | G7: 44874 | H7: 330301004 | I7: 201 | J7: 11 | K7: Debito | L7: EM | M7: EM - NF (909090909) P: (11010003 ) F: (000003) | O7: 000054 | P7: 000132 | Q7: 25 | R7: 0,00 | S7: 0,00 | T7: 0,00 | U7: 0,00 | X7: 201 | Y7: 11 | AB7: 010101
A8: =IFERROR(VLOOKUP(H8,'Contas Orç'!A:B,2,0),"N/A") -> PECAS E ACESSORIOS | B8: =_xlfn.CONCAT(H8," - ",A8) -> 320301004 - PECAS E ACESSORIOS | C8: =DATE(YEAR(G8),MONTH(G8),1) -> 44866 | D8: =IF(K8="CREDITO",Q8,Q8*-1) -> 345 | E8: 0000000003 | F8: 0001 | G8: 44876 | H8: 320301004 | I8: 301 | J8: 90 | K8: Credito | L8: EM | M8: EM - PEDIDO (000146) | (11280021 ) | F: (000361/0001) | O8: 000055 | P8: 000132 | Q8: 345 | R8: 0,00 | S8: 0,00 | T8: 0,00 | U8: 0,00 | V8: ORC2022 | Y8: 90 | AB8: 010101
A9: =IFERROR(VLOOKUP(H9,'Contas Orç'!A:B,2,0),"N/A") -> N/A | B9: =_xlfn.CONCAT(H9," - ",A9) -> - N/A | C9: =DATE(YEAR(G9),MONTH(G9),1) -> 44866 | D9: =IF(K9="CREDITO",Q9,Q9*-1) -> 170000 | E9: 0000000004 | F9: 0001 | G9: 44879 | I9: 305 | J9: 21 | K9: Credito | L9: EM | M9: EM - PEDIDO (011661) ITEM +(0001) / (EMPILHADEIRA HYSTER H50 | O9: 000055 | P9: 000044 | Q9: 170000 | R9: 0,00 | S9: 0,00 | T9: 0,00 | U9: 0,00 | X9: 305 | Y9: 21 | AB9: 010101
A10: =IFERROR(VLOOKUP(H10,'Contas Orç'!A:B,2,0),"N/A") -> N/A | B10: =_xlfn.CONCAT(H10," - ",A10) -> - N/A | C10: =DATE(YEAR(G10),MONTH(G10),1) -> 44866 | D10: =IF(K10="CREDITO",Q10,Q10*-1) -> 172000 | E10: 0000000004 | F10: 0002 | G10: 44879 | I10: 305 | J10: 21 | K10: Credito | L10: EM | M10: EM - PEDIDO (011661) ITEM +(0002) / (EMPILHADEIRA HYSTER H50 | O10: 000055 | P10: 000044 | Q10: 172000 | R10: 0,00 | S10: 0,00 | T10: 0,00 | U10: 0,00 | X10: 305 | Y10: 21 | AB10: 010101
A11: =IFERROR(VLOOKUP(H11,'Contas Orç'!A:B,2,0),"N/A") -> PJ-OUTROS SERVICOS CONTRATADOS-PJ | B11: =_xlfn.CONCAT(H11," - ",A11) -> 330201006 - PJ-OUTROS SERVICOS CONTRATADOS-PJ | C11: =DATE(YEAR(G11),MONTH(G11),1) -> 44866 | D11: =IF(K11="CREDITO",Q11,Q11*-1) -> 33809 | E11: 0000000005 | F11: 0001 | G11: 44879 | H11: 330201006 | I11: 211 | J11: 51 | K11: Credito | L11: EM | M11: EM - PEDIDO (013494) ITEM +(0001) / (SERVICO DE EMPREITADA / | O11: 000055 | P11: 000000 | Q11: 33809 | R11: 0,00 | S11: 0,00 | T11: 0,00 | U11: 0,00 | X11: 211 | Y11: 51 | AB11: 010101
A12: =IFERROR(VLOOKUP(H12,'Contas Orç'!A:B,2,0),"N/A") -> BENEFICIOS | B12: =_xlfn.CONCAT(H12," - ",A12) -> 330103 - BENEFICIOS | C12: =DATE(YEAR(G12),MONTH(G12),1) -> 44866 | D12: =IF(K12="CREDITO",Q12,Q12*-1) -> 655 | E12: 0000000007 | F12: 0001 | G12: 44879 | H12: 330103 | I12: 207 | J12: 90 | K12: Credito | L12: EM | M12: EM - PEDIDO (013492) ITEM +(0001) / (ASSISTENCIA MEDICA | O12: 000055 | P12: 000000 | Q12: 655 | R12: 0,00 | S12: 0,00 | T12: 0,00 | U12: 0,00 | X12: 207 | Y12: 90 | AB12: 010101
A13: =IFERROR(VLOOKUP(H13,'Contas Orç'!A:B,2,0),"N/A") -> BENEFICIOS | B13: =_xlfn.CONCAT(H13," - ",A13) -> 330103 - BENEFICIOS | C13: =DATE(YEAR(G13),MONTH(G13),1) -> 44866 | D13: =IF(K13="CREDITO",Q13,Q13*-1) -> 1267 | E13: 0000000007 | F13: 0002 | G13: 44879 | H13: 330103 | I13: 208 | J13: 90 | K13: Credito | L13: EM | M13: EM - PEDIDO (013492) ITEM +(0002) / (ASSISTENCIA MEDICA | O13: 000055 | P13: 000000 | Q13: 1267 | R13: 0,00 | S13: 0,00 | T13: 0,00 | U13: 0,00 | X13: 208 | Y13: 90 | AB13: 010101
A14: =IFERROR(VLOOKUP(H14,'Contas Orç'!A:B,2,0),"N/A") -> BENEFICIOS | B14: =_xlfn.CONCAT(H14," - ",A14) -> 330103 - BENEFICIOS | C14: =DATE(YEAR(G14),MONTH(G14),1) -> 44866 | D14: =IF(K14="CREDITO",Q14,Q14*-1) -> 516 | E14: 0000000007 | F14: 0003 | G14: 44879 | H14: 330103 | I14: 209 | J14: 90 | K14: Credito | L14: EM | M14: EM - PEDIDO (013492) ITEM +(0003) / (ASSISTENCIA MEDICA | O14: 000055 | P14: 000000 | Q14: 516 | R14: 0,00 | S14: 0,00 | T14: 0,00 | U14: 0,00 | X14: 209 | Y14: 90 | AB14: 010101
A15: =IFERROR(VLOOKUP(H15,'Contas Orç'!A:B,2,0),"N/A") -> BENEFICIOS | B15: =_xlfn.CONCAT(H15," - ",A15) -> 320103 - BENEFICIOS | C15: =DATE(YEAR(G15),MONTH(G15),1) -> 44866 | D15: =IF(K15="CREDITO",Q15,Q15*-1) -> 3874 | E15: 0000000007 | F15: 0004 | G15: 44879 | H15: 320103 | I15: 301 | J15: 11 | K15: Credito | L15: EM | M15: EM - PEDIDO (013492) ITEM +(0004) / (ASSISTENCIA MEDICA | O15: 000055 | P15: 000000 | Q15: 3874 | R15: 0,00 | S15: 0,00 | T15: 0,00 | U15: 0,00 | X15: 301 | Y15: 11 | AB15: 010101
A16: =IFERROR(VLOOKUP(H16,'Contas Orç'!A:B,2,0),"N/A") -> BENEFICIOS | B16: =_xlfn.CONCAT(H16," - ",A16) -> 320103 - BENEFICIOS | C16: =DATE(YEAR(G16),MONTH(G16),1) -> 44866 | D16: =IF(K16="CREDITO",Q16,Q16*-1) -> 4905 | E16: 0000000007 | F16: 0005 | G16: 44879 | H16: 320103 | I16: 302 | J16: 11 | K16: Credito | L16: EM | M16: EM - PEDIDO (013492) ITEM +(0005) / (ASSISTENCIA MEDICA | O16: 000055 | P16: 000000 | Q16: 4905 | R16: 0,00 | S16: 0,00 | T16: 0,00 | U16: 0,00 | X16: 302 | Y16: 11 | AB16: 010101
A17: =IFERROR(VLOOKUP(H17,'Contas Orç'!A:B,2,0),"N/A") -> BENEFICIOS | B17: =_xlfn.CONCAT(H17," - ",A17) -> 320103 - BENEFICIOS | C17: =DATE(YEAR(G17),MONTH(G17),1) -> 44866 | D17: =IF(K17="CREDITO",Q17,Q17*-1) -> 11568 | E17: 0000000007 | F17: 0006 | G17: 44879 | H17: 320103 | I17: 304 | J17: 21 | K17: Credito | L17: EM | M17: EM - PEDIDO (013492) ITEM +(0006) / (ASSISTENCIA MEDICA | O17: 000055 | P17: 000000 | Q17: 11568 | R17: 0,00 | S17: 0,00 | T17: 0,00 | U17: 0,00 | X17: 304 | Y17: 21 | AB17: 010101
A18: =IFERROR(VLOOKUP(H18,'Contas Orç'!A:B,2,0),"N/A") -> BENEFICIOS | B18: =_xlfn.CONCAT(H18," - ",A18) -> 320103 - BENEFICIOS | C18: =DATE(YEAR(G18),MONTH(G18),1) -> 44866 | D18: =IF(K18="CREDITO",Q18,Q18*-1) -> 608 | E18: 0000000007 | F18: 0007 | G18: 44879 | H18: 320103 | I18: 305 | J18: 33 | K18: Credito | L18: EM | M18: EM - PEDIDO (013492) ITEM +(0007) / (ASSISTENCIA MEDICA | O18: 000055 | P18: 000000 | Q18: 608 | R18: 0,00 | S18: 0,00 | T18: 0,00 | U18: 0,00 | X18: 305 | Y18: 33 | AB18: 010101
A19: =IFERROR(VLOOKUP(H19,'Contas Orç'!A:B,2,0),"N/A") -> BENEFICIOS | B19: =_xlfn.CONCAT(H19," - ",A19) -> 330103 - BENEFICIOS | C19: =DATE(YEAR(G19),MONTH(G19),1) -> 44866 | D19: =IF(K19="CREDITO",Q19,Q19*-1) -> 563 | E19: 0000000007 | F19: 0008 | G19: 44879 | H19: 330103 | I19: 206 | J19: 90 | K19: Credito | L19: EM | M19: EM - PEDIDO (013492) ITEM +(0008) / (ASSISTENCIA MEDICA | O19: 000055 | P19: 000000 | Q19: 563 | R19: 0,00 | S19: 0,00 | T19: 0,00 | U19: 0,00 | X19: 206 | Y19: 90 | AB19: 010101
A20: =IFERROR(VLOOKUP(H20,'Contas Orç'!A:B,2,0),"N/A") -> BENEFICIOS | B20: =_xlfn.CONCAT(H20," - ",A20) -> 320103 - BENEFICIOS | C20: =DATE(YEAR(G20),MONTH(G20),1) -> 44866 | D20: =IF(K20="CREDITO",Q20,Q20*-1) -> 704 | E20: 0000000007 | F20: 0009 | G20: 44879 | H20: 320103 | I20: 301 | J20: 90 | K20: Credito | L20: EM | M20: EM - PEDIDO (013492) ITEM +(0009) / (ASSISTENCIA MEDICA | O20: 000055 | P20: 000000 | Q20: 704 | R20: 0,00 | S20: 0,00 | T20: 0,00 | U20: 0,00 | X20: 301 | Y20: 90 | AB20: 010101
A21: =IFERROR(VLOOKUP(H21,'Contas Orç'!A:B,2,0),"N/A") -> BENEFICIOS | B21: =_xlfn.CONCAT(H21," - ",A21) -> 320103 - BENEFICIOS | C21: =DATE(YEAR(G21),MONTH(G21),1) -> 44866 | D21: =IF(K21="CREDITO",Q21,Q21*-1) -> 11421 | E21: 0000000007 | F21: 0010 | G21: 44879 | H21: 320103 | I21: 303 | J21: 31 | K21: Credito | L21: EM | M21: EM - PEDIDO (013492) ITEM +(0010) / (ASSISTENCIA MEDICA | O21: 000055 | P21: 000000 | Q21: 11421 | R21: 0,00 | S21: 0,00 | T21: 0,00 | U21: 0,00 | X21: 303 | Y21: 31 | AB21: 010101
A22: =IFERROR(VLOOKUP(H22,'Contas Orç'!A:B,2,0),"N/A") -> BENEFICIOS | B22: =_xlfn.CONCAT(H22," - ",A22) -> 320103 - BENEFICIOS | C22: =DATE(YEAR(G22),MONTH(G22),1) -> 44866 | D22: =IF(K22="CREDITO",Q22,Q22*-1) -> 71588 | E22: 0000000007 | F22: 0011 | G22: 44879 | H22: 320103 | I22: 305 | J22: 90 | K22: Credito | L22: EM | M22: EM - PEDIDO (013492) ITEM +(0011) / (ASSISTENCIA MEDICA | O22: 000055 | P22: 000000 | Q22: 71588 | R22: 0,00 | S22: 0,00 | T22: 0,00 | U22: 0,00 | X22: 305 | Y22: 90 | AB22: 010101
... A114: =IFERROR(VLOOKUP(H114,'Contas Orç'!A:B,2,0),"N/A") -> PJ-OUTROS SERVICOS CONTRATADOS-PJ | B114: =_xlfn.CONCAT(H114," - ",A114) -> 330201006 - PJ-OUTROS SERVICOS CONTRATADOS-PJ | C114: =DATE(YEAR(G114),MONTH(G114),1) -> 44866 | D114: =IF(K114="CREDITO",Q114,Q114*-1) -> -33809 | E114: 0000000025 | F114: 0002 | G114: 44879 | H114: 330201006 | I114: 211 | J114: 51 | K114: Debito | L114: EM | M114: EM - PED (013494) PROD: (23010001) / FOR: (ROYAL CONSTRUCOES | O114: 000054 | P114: 000132 | Q114: 33809 | R114: 0,00 | S114: 0,00 | T114: 0,00 | U114: 0,00 | X114: 211 | Y114: 51 | AB114: 010101
A115: =IFERROR(VLOOKUP(H115,'Contas Orç'!A:B,2,0),"N/A") -> N/A | B115: =_xlfn.CONCAT(H115," - ",A115) -> - N/A | C115: =DATE(YEAR(G115),MONTH(G115),1) -> 44866 | D115: =IF(K115="CREDITO",Q115,Q115*-1) -> 170000 | E115: 0000000026 | F115: 0001 | G115: 44882 | I115: 305 | J115: 21 | K115: Credito | L115: EM | M115: EM - PED (013495) PROD: (42010009) / FOR: (HYSTER YALE BRASI | O115: 000055 | P115: 000000 | Q115: 170000 | R115: 0,00 | S115: 0,00 | T115: 0,00 | U115: 0,00 | X115: 305 | Y115: 21 | AB115: 010101
A116: =IFERROR(VLOOKUP(H116,'Contas Orç'!A:B,2,0),"N/A") -> N/A | B116: =_xlfn.CONCAT(H116," - ",A116) -> - N/A | C116: =DATE(YEAR(G116),MONTH(G116),1) -> 44866 | D116: =IF(K116="CREDITO",Q116,Q116*-1) -> 172000 | E116: 0000000026 | F116: 0002 | G116: 44882 | I116: 305 | J116: 21 | K116: Credito | L116: EM | M116: EM - PED (013495) PROD: (42010008) / FOR: (HYSTER YALE BRASI | O116: 000055 | P116: 000000 | Q116: 172000 | R116: 0,00 | S116: 0,00 | T116: 0,00 | U116: 0,00 | X116: 305 | Y116: 21 | AB116: 010101
A117: =IFERROR(VLOOKUP(H117,'Contas Orç'!A:B,2,0),"N/A") -> COMBUSTIVEIS | B117: =_xlfn.CONCAT(H117," - ",A117) -> 330301001 - COMBUSTIVEIS | C117: =DATE(YEAR(G117),MONTH(G117),1) -> 44866 | D117: =IF(K117="CREDITO",Q117,Q117*-1) -> 64090 | E117: 0000000027 | F117: 0001 | G117: 44882 | H117: 330301001 | I117: 209 | J117: 11 | K117: Credito | L117: EM | M117: EM - PED (013496) PROD: (11100008) / FOR: (PETROTUDO COMERCI | O117: 000055 | P117: 000000 | Q117: 64090 | R117: 0,00 | S117: 0,00 | T117: 0,00 | U117: 0,00 | X117: 209 | Y117: 11 | AB117: 010101
A118: =IFERROR(VLOOKUP(H118,'Contas Orç'!A:B,2,0),"N/A") -> COMBUSTIVEIS | B118: =_xlfn.CONCAT(H118," - ",A118) -> 330301001 - COMBUSTIVEIS | C118: =DATE(YEAR(G118),MONTH(G118),1) -> 44866 | D118: =IF(K118="CREDITO",Q118,Q118*-1) -> 64090 | E118: 0000000027 | F118: 0002 | G118: 44882 | H118: 330301001 | I118: 209 | J118: 21 | K118: Credito | L118: EM | M118: EM - PED (013496) PROD: (11100008) / FOR: (PETROTUDO COMERCI | O118: 000055 | P118: 000000 | Q118: 64090 | R118: 0,00 | S118: 0,00 | T118: 0,00 | U118: 0,00 | X118: 209 | Y118: 21 | AB118: 010101
A119: =IFERROR(VLOOKUP(H119,'Contas Orç'!A:B,2,0),"N/A") -> PECAS E ACESSORIOS | B119: =_xlfn.CONCAT(H119," - ",A119) -> 320301004 - PECAS E ACESSORIOS | C119: =DATE(YEAR(G119),MONTH(G119),1) -> 44866 | D119: =IF(K119="CREDITO",Q119,Q119*-1) -> 398 | E119: 0000000028 | F119: 0001 | G119: 44882 | H119: 320301004 | I119: 304 | J119: 11 | K119: Credito | L119: EM | M119: EM - PED (013500) PROD: (22010002) / FOR: (FREIO DIESEL PECA | O119: 000055 | P119: 000000 | Q119: 398 | R119: 0,00 | S119: 0,00 | T119: 0,00 | U119: 0,00 | X119: 304 | Y119: 11 | AB119: 010101
A120: =IFERROR(VLOOKUP(H120,'Contas Orç'!A:B,2,0),"N/A") -> PJ-OUTROS SERVICOS CONTRATADOS-PJ | B120: =_xlfn.CONCAT(H120," - ",A120) -> 330201006 - PJ-OUTROS SERVICOS CONTRATADOS-PJ | C120: =DATE(YEAR(G120),MONTH(G120),1) -> 44866 | D120: =IF(K120="CREDITO",Q120,Q120*-1) -> 499 | E120: 0000000029 | F120: 0001 | G120: 44882 | H120: 330201006 | I120: 201 | J120: 90 | K120: Credito | L120: EM | M120: EM - PED (013499) PROD: (23010016) / FOR: (APROVADOR SISTEMA | O120: 000055 | P120: 000000 | Q120: 499 | R120: 0,00 | S120: 0,00 | T120: 0,00 | U120: 0,00 | X120: 201 | Y120: 90 | AB120: 010101
A121: =IFERROR(VLOOKUP(H121,'Contas Orç'!A:B,2,0),"N/A") -> PJ-OUTROS SERVICOS CONTRATADOS-PJ | B121: =_xlfn.CONCAT(H121," - ",A121) -> 330201006 - PJ-OUTROS SERVICOS CONTRATADOS-PJ | C121: =DATE(YEAR(G121),MONTH(G121),1) -> 44866 | D121: =IF(K121="CREDITO",Q121,Q121*-1) -> 499 | E121: 0000000029 | F121: 0002 | G121: 44882 | H121: 330201006 | I121: 201 | J121: 90 | K121: Credito | L121: EM | M121: EM - PED (013499) PROD: (23010016) / FOR: (APROVADOR SISTEMA | O121: 000055 | P121: 000000 | Q121: 499 | R121: 0,00 | S121: 0,00 | T121: 0,00 | U121: 0,00 | X121: 201 | Y121: 90 | AB121: 010101
A122: =IFERROR(VLOOKUP(H122,'Contas Orç'!A:B,2,0),"N/A") -> PJ-OUTROS SERVICOS CONTRATADOS-PJ | B122: =_xlfn.CONCAT(H122," - ",A122) -> 330201006 - PJ-OUTROS SERVICOS CONTRATADOS-PJ | C122: =DATE(YEAR(G122),MONTH(G122),1) -> 44866 | D122: =IF(K122="CREDITO",Q122,Q122*-1) -> 499 | E122: 0000000029 | F122: 0003 | G122: 44882 | H122: 330201006 | I122: 201 | J122: 90 | K122: Credito | L122: EM | M122: EM - PED (013499) PROD: (23010016) / FOR: (APROVADOR SISTEMA | O122: 000055 | P122: 000000 | Q122: 499 | R122: 0,00 | S122: 0,00 | T122: 0,00 | U122: 0,00 | X122: 201 | Y122: 90 | AB122: 010101
A123: =IFERROR(VLOOKUP(H123,'Contas Orç'!A:B,2,0),"N/A") -> PJ-OUTROS SERVICOS CONTRATADOS-PJ | B123: =_xlfn.CONCAT(H123," - ",A123) -> 330201006 - PJ-OUTROS SERVICOS CONTRATADOS-PJ | C123: =DATE(YEAR(G123),MONTH(G123),1) -> 44866 | D123: =IF(K123="CREDITO",Q123,Q123*-1) -> 499 | E123: 0000000029 | F123: 0004 | G123: 44882 | H123: 330201006 | I123: 201 | J123: 90 | K123: Credito | L123: EM | M123: EM - PED (013499) PROD: (23010016) / FOR: (APROVADOR SISTEMA | O123: 000055 | P123: 000000 | Q123: 499 | R123: 0,00 | S123: 0,00 | T123: 0,00 | U123: 0,00 | X123: 201 | Y123: 90 | AB123: 010101
A124: =IFERROR(VLOOKUP(H124,'Contas Orç'!A:B,2,0),"N/A") -> PJ-OUTROS SERVICOS CONTRATADOS-PJ | B124: =_xlfn.CONCAT(H124," - ",A124) -> 330201006 - PJ-OUTROS SERVICOS CONTRATADOS-PJ | C124: =DATE(YEAR(G124),MONTH(G124),1) -> 44866 | D124: =IF(K124="CREDITO",Q124,Q124*-1) -> 499 | E124: 0000000029 | F124: 0005 | G124: 44882 | H124: 330201006 | I124: 201 | J124: 90 | K124: Credito | L124: EM | M124: EM - PED (013499) PROD: (23010016) / FOR: (APROVADOR SISTEMA | O124: 000055 | P124: 000000 | Q124: 499 | R124: 0,00 | S124: 0,00 | T124: 0,00 | U124: 0,00 | X124: 201 | Y124: 90 | AB124: 010101
A125: =IFERROR(VLOOKUP(H125,'Contas Orç'!A:B,2,0),"N/A") -> PJ-OUTROS SERVICOS CONTRATADOS-PJ | B125: =_xlfn.CONCAT(H125," - ",A125) -> 330201006 - PJ-OUTROS SERVICOS CONTRATADOS-PJ | C125: =DATE(YEAR(G125),MONTH(G125),1) -> 44866 | D125: =IF(K125="CREDITO",Q125,Q125*-1) -> 499 | E125: 0000000029 | F125: 0006 | G125: 44882 | H125: 330201006 | I125: 201 | J125: 90 | K125: Credito | L125: EM | M125: EM - PED (013499) PROD: (23010016) / FOR: (APROVADOR SISTEMA | O125: 000055 | P125: 000000 | Q125: 499 | R125: 0,00 | S125: 0,00 | T125: 0,00 | U125: 0,00 | X125: 201 | Y125: 90 | AB125: 010101
A126: =IFERROR(VLOOKUP(H126,'Contas Orç'!A:B,2,0),"N/A") -> PJ-LOCACAO DE MAQUINAS E EQUIPAMENTO | B126: =_xlfn.CONCAT(H126," - ",A126) -> 320201004 - PJ-LOCACAO DE MAQUINAS E EQUIPAMENTO | C126: =DATE(YEAR(G126),MONTH(G126),1) -> 44866 | D126: =IF(K126="CREDITO",Q126,Q126*-1) -> 3631 | E126: 0000000030 | F126: 0001 | G126: 44882 | H126: 320201004 | I126: 301 | J126: 90 | K126: Credito | L126: EM | M126: EM - PED (013498) PROD: (23010005) / FOR: (COMPANHIA DE LOCA | O126: 000055 | P126: 000000 | Q126: 3631 | R126: 0,00 | S126: 0,00 | T126: 0,00 | U126: 0,00 | X126: 301 | Y126: 90 | AB126: 010101
A127: =IFERROR(VLOOKUP(H127,'Contas Orç'!A:B,2,0),"N/A") -> PJ-LOCACAO DE MAQUINAS E EQUIPAMENTO | B127: =_xlfn.CONCAT(H127," - ",A127) -> 320201004 - PJ-LOCACAO DE MAQUINAS E EQUIPAMENTO | C127: =DATE(YEAR(G127),MONTH(G127),1) -> 44866 | D127: =IF(K127="CREDITO",Q127,Q127*-1) -> 3701 | E127: 0000000030 | F127: 0002 | G127: 44882 | H127: 320201004 | I127: 301 | J127: 90 | K127: Credito | L127: EM | M127: EM - PED (013498) PROD: (23010005) / FOR: (COMPANHIA DE LOCA | O127: 000055 | P127: 000000 | Q127: 3701 | R127: 0,00 | S127: 0,00 | T127: 0,00 | U127: 0,00 | X127: 301 | Y127: 90 | AB127: 010101
A128: =IFERROR(VLOOKUP(H128,'Contas Orç'!A:B,2,0),"N/A") -> PJ-LOCACAO DE MAQUINAS E EQUIPAMENTO | B128: =_xlfn.CONCAT(H128," - ",A128) -> 320201004 - PJ-LOCACAO DE MAQUINAS E EQUIPAMENTO | C128: =DATE(YEAR(G128),MONTH(G128),1) -> 44866 | D128: =IF(K128="CREDITO",Q128,Q128*-1) -> 1885 | E128: 0000000030 | F128: 0003 | G128: 44882 | H128: 320201004 | I128: 301 | J128: 90 | K128: Credito | L128: EM | M128: EM - PED (013498) PROD: (23010005) / FOR: (COMPANHIA DE LOCA | O128: 000055 | P128: 000000 | Q128: 1885 | R128: 0,00 | S128: 0,00 | T128: 0,00 | U128: 0,00 | X128: 301 | Y128: 90 | AB128: 010101
... A260: =IFERROR(VLOOKUP(H260,'Contas Orç'!A:B,2,0),"N/A") -> PJ-OUTROS SERVICOS CONTRATADOS-PJ | B260: =_xlfn.CONCAT(H260," - ",A260) -> 330201006 - PJ-OUTROS SERVICOS CONTRATADOS-PJ | C260: =DATE(YEAR(G260),MONTH(G260),1) -> 44866 | D260: =IF(K260="CREDITO",Q260,Q260*-1) -> -586.34 | E260: 0000000077 | F260: 0002 | G260: 44886 | H260: 330201006 | I260: 201 | J260: 90 | K260: Debito | L260: EM | M260: EM - PED (013507) PROD: (23010006) / FOR: (BERNUTTY TECHNOLO | O260: 000054 | P260: 000070 | Q260: 586.34 | R260: 0,00 | S260: 0,00 | T260: 0,00 | U260: 0,00 | X260: 201 | Y260: 90 | AB260: 010101
A261: =IFERROR(VLOOKUP(H261,'Contas Orç'!A:B,2,0),"N/A") -> RECEITA BRUTA DE TRANSPORTES | B261: =_xlfn.CONCAT(H261," - ",A261) -> 310101 - RECEITA BRUTA DE TRANSPORTES | C261: =DATE(YEAR(G261),MONTH(G261),1) -> 44866 | D261: =IF(K261="CREDITO",Q261,Q261*-1) -> 1582.57 | E261: 0000000078 | F261: 0001 | G261: 44888 | H261: 310101 | I261: 304 | J261: 11 | K261: Credito | L261: RE | M261: RE - NF (000053700) P: (21010001) C: (HAMBURG SUD A/S) | O261: 000101 | P261: 000132 | Q261: 1582.57 | R261: 0,00 | S261: 0,00 | T261: 0,00 | U261: 0,00 | V261: ORC2022_2 | X261: 304 | Y261: 11 | AB261: 010101
A262: =IFERROR(VLOOKUP(H262,'Contas Orç'!A:B,2,0),"N/A") -> IMOBILIZADO EM ANDAMENTO - PROPRIOS | B262: =_xlfn.CONCAT(H262," - ",A262) -> 120307001 - IMOBILIZADO EM ANDAMENTO - PROPRIOS | C262: =DATE(YEAR(G262),MONTH(G262),1) -> 44866 | D262: =IF(K262="CREDITO",Q262,Q262*-1) -> 241.77 | E262: 0000000079 | F262: 0001 | G262: 44888 | H262: 120307001 | I262: 211 | J262: 51 | K262: Credito | L262: EM | M262: EM - PED (013508) PROD: (11100029) / FOR: (POSTO PECEM COMER | O262: 000055 | P262: 000000 | Q262: 241.77 | R262: 0,00 | S262: 0,00 | T262: 0,00 | U262: 0,00 | V262: ORC2022_2 | X262: 211 | Y262: 51 | AB262: 010101
...

Sheet Base_24.11
A1: Desc_Conta | B1: VERIFICAÇÃO | C1: Lote | D1: Item | E1: Data | F1: C.O. | G1: Classe | H1: Operacao | I1: Tipo | J1: Tp. Saldo | K1: Historico | L1: Unid. Medida | M1: Processo | N1: Usuario | O1: Vlr.Lancto. | P1: Vlr.2a Moeda | Q1: Vlr.3a Moeda | R1: Vlr.4a Moeda | S1: Vlr.5a Moeda | T1: Cod.Planilha | U1: Versao | V1: Centro Custo | W1: It.Contabil | X1: Classe Valor | Y1: Lc.Bloqueio? | Z1: Und. Orc.
A2: =VLOOKUP(F2,'Contas Orç'!A:B,2,0) -> PECAS E ACESSORIOS | B2: =VLOOKUP(C2,Base_20.12!E:E,1,0) -> 0000000001 | C2: 0000000001 | D2: 0001 | E2: 44874 | F2: 320301004 | G2: 304 | H2: 11 | I2: Credito | J2: EM | K2: EM - PEDIDO (013491) ITEM +(0001) / (ITERRUPTOR DO NEUTRO - | M2: 000052 | N2: 000132 | O2: 25,00 | P2: 0,00 | Q2: 0,00 | R2: 0,00 | S2: 0,00 | T2: ORC2022 | V2: 304 | W2: 11 | Z2: 010101
A3: =VLOOKUP(F3,'Contas Orç'!A:B,2,0) -> PECAS E ACESSORIOS | B3: =VLOOKUP(C3,Base_20.12!E:E,1,0) -> 0000000001 | C3: 0000000001 | D3: 0002 | E3: 44874 | F3: 330301004 | G3: 201 | H3: 11 | I3: Credito | J3: EM | K3: EM - PEDIDO (013491) ITEM +(0002) / (MANCAL PARA LOCK (GUIA | M3: 000052 | N3: 000132 | O3: 25,00 | P3: 0,00 | Q3: 0,00 | R3: 0,00 | S3: 0,00 | T3: ORC2022 | V3: 201 | W3: 11 | Z3: 010101
A4: =VLOOKUP(F4,'Contas Orç'!A:B,2,0) -> PECAS E ACESSORIOS | B4: =VLOOKUP(C4,Base_20.12!E:E,1,0) -> 0000000002 | C4: 0000000002 | D4: 0001 | E4: 44874 | F4: 320301004 | G4: 304 | H4: 11 | I4: Credito | J4: RE | K4: RE - NF (909090909) P: (11150482 ) F: (000003) | M4: 000054 | N4: 000132 | O4: 25,00 | P4: 0,00 | Q4: 0,00 | R4: 0,00 | S4: 0,00 | V4: 304 | W4: 11 | Z4: 010101
A5: =VLOOKUP(F5,'Contas Orç'!A:B,2,0) -> PECAS E ACESSORIOS | B5: =VLOOKUP(C5,Base_20.12!E:E,1,0) -> 0000000002 | C5: 0000000002 | D5: 0002 | E5: 44874 | F5: 320301004 | G5: 304 | H5: 11 | I5: Debito | J5: EM | K5: EM - NF (909090909) P: (11150482 ) F: (000003) | M5: 000054 | N5: 000132 | O5: 25,00 | P5: 0,00 | Q5: 0,00 | R5: 0,00 | S5: 0,00 | V5: 304 | W5: 11 | Z5: 010101
A6: =VLOOKUP(F6,'Contas Orç'!A:B,2,0) -> PECAS E ACESSORIOS | B6: =VLOOKUP(C6,Base_20.12!E:E,1,0) -> 0000000002 | C6: 0000000002 | D6: 0003 | E6: 44874 | F6: 330301004 | G6: 201 | H6: 11 | I6: Credito | J6: RE | K6: RE - NF (909090909) P: (11010003 ) F: (000003) | M6: 000054 | N6: 000132 | O6: 25,00 | P6: 0,00 | Q6: 0,00 | R6: 0,00 | S6: 0,00 | V6: 201 | W6: 11 | Z6: 010101
A7: =VLOOKUP(F7,'Contas Orç'!A:B,2,0) -> PECAS E ACESSORIOS | B7: =VLOOKUP(C7,Base_20.12!E:E,1,0) -> 0000000002 | C7: 0000000002 | D7: 0004 | E7: 44874 | F7: 330301004 | G7: 201 | H7: 11 | I7: Debito | J7: EM | K7: EM - NF (909090909) P: (11010003 ) F: (000003) | M7: 000054 | N7: 000132 | O7: 25,00 | P7: 0,00 | Q7: 0,00 | R7: 0,00 | S7: 0,00 | V7: 201 | W7: 11 | Z7: 010101
A8: =VLOOKUP(F8,'Contas Orç'!A:B,2,0) -> PECAS E ACESSORIOS | B8: =VLOOKUP(C8,Base_20.12!E:E,1,0) -> 0000000003 | C8: 0000000003 | D8: 0001 | E8: 44876 | F8: 320301004 | G8: 301 | H8: 90 | I8: Credito | J8: EM | K8: EM - PEDIDO (000146) | (11280021 ) | F: (000361/0001) | M8: 000055 | N8: 000132 | O8: 345,00 | P8: 0,00 | Q8: 0,00 | R8: 0,00 | S8: 0,00 | T8: ORC2022 | W8: 90 | Z8: 010101
A9: =VLOOKUP(F9,'Contas Orç'!A:B,2,0) -> #N/A | B9: =VLOOKUP(C9,Base_20.12!E:E,1,0) -> 0000000004 | C9: 0000000004 | D9: 0001 | E9: 44879 | G9: 305 | H9: 21 | I9: Credito | J9: EM | K9: EM - PEDIDO (011661) ITEM +(0001) / (EMPILHADEIRA HYSTER H50 | M9: 000055 | N9: 000044 | O9: 170.000,00 | P9: 0,00 | Q9: 0,00 | R9: 0,00 | S9: 0,00 | V9: 305 | W9: 21 | Z9: 010101
A10: =VLOOKUP(F10,'Contas Orç'!A:B,2,0) -> #N/A | B10: =VLOOKUP(C10,Base_20.12!E:E,1,0) -> 0000000004 | C10: 0000000004 | D10: 0002 | E10: 44879 | G10: 305 | H10: 21 | I10: Credito | J10: EM | K10: EM - PEDIDO (011661) ITEM +(0002) / (EMPILHADEIRA HYSTER H50 | M10: 000055 | N10: 000044 | O10: 172.000,00 | P10: 0,00 | Q10: 0,00 | R10: 0,00 | S10: 0,00 | V10: 305 | W10: 21 | Z10: 010101
A11: =VLOOKUP(F11,'Contas Orç'!A:B,2,0) -> PJ-OUTROS SERVICOS CONTRATADOS-PJ | B11: =VLOOKUP(C11,Base_20.12!E:E,1,0) -> 0000000005 | C11: 0000000005 | D11: 0001 | E11: 44879 | F11: 330201006 | G11: 211 | H11: 51 | I11: Credito | J11: EM | K11: EM - PEDIDO (013494) ITEM +(0001) / (SERVICO DE EMPREITADA / | M11: 000055 | N11: 000000 | O11: 33.809,00 | P11: 0,00 | Q11: 0,00 | R11: 0,00 | S11: 0,00 | V11: 211 | W11: 51 | Z11: 010101
A12: =VLOOKUP(F12,'Contas Orç'!A:B,2,0) -> BENEFICIOS | B12: =VLOOKUP(C12,Base_20.12!E:E,1,0) -> 0000000007 | C12: 0000000007 | D12: 0001 | E12: 44879 | F12: 330103 | G12: 207 | H12: 90 | I12: Credito | J12: EM | K12: EM - PEDIDO (013492) ITEM +(0001) / (ASSISTENCIA MEDICA | M12: 000055 | N12: 000000 | O12: 655,00 | P12: 0,00 | Q12: 0,00 | R12: 0,00 | S12: 0,00 | V12: 207 | W12: 90 | Z12: 010101
A13: =VLOOKUP(F13,'Contas Orç'!A:B,2,0) -> BENEFICIOS | B13: =VLOOKUP(C13,Base_20.12!E:E,1,0) -> 0000000007 | C13: 0000000007 | D13: 0002 | E13: 44879 | F13: 330103 | G13: 208 | H13: 90 | I13: Credito | J13: EM | K13: EM - PEDIDO (013492) ITEM +(0002) / (ASSISTENCIA MEDICA | M13: 000055 | N13: 000000 | O13: 1.267,00 | P13: 0,00 | Q13: 0,00 | R13: 0,00 | S13: 0,00 | V13: 208 | W13: 90 | Z13: 010101
A14: =VLOOKUP(F14,'Contas Orç'!A:B,2,0) -> BENEFICIOS | B14: =VLOOKUP(C14,Base_20.12!E:E,1,0) -> 0000000007 | C14: 0000000007 | D14: 0003 | E14: 44879 | F14: 330103 | G14: 209 | H14: 90 | I14: Credito | J14: EM | K14: EM - PEDIDO (013492) ITEM +(0003) / (ASSISTENCIA MEDICA | M14: 000055 | N14: 000000 | O14: 516,00 | P14: 0,00 | Q14: 0,00 | R14: 0,00 | S14: 0,00 | V14: 209 | W14: 90 | Z14: 010101
A15: =VLOOKUP(F15,'Contas Orç'!A:B,2,0) -> BENEFICIOS | B15: =VLOOKUP(C15,Base_20.12!E:E,1,0) -> 0000000007 | C15: 0000000007 | D15: 0004 | E15: 44879 | F15: 320103 | G15: 301 | H15: 11 | I15: Credito | J15: EM | K15: EM - PEDIDO (013492) ITEM +(0004) / (ASSISTENCIA MEDICA | M15: 000055 | N15: 000000 | O15: 3.874,00 | P15: 0,00 | Q15: 0,00 | R15: 0,00 | S15: 0,00 | V15: 301 | W15: 11 | Z15: 010101
A16: =VLOOKUP(F16,'Contas Orç'!A:B,2,0) -> BENEFICIOS | B16: =VLOOKUP(C16,Base_20.12!E:E,1,0) -> 0000000007 | C16: 0000000007 | D16: 0005 | E16: 44879 | F16: 320103 | G16: 302 | H16: 11 | I16: Credito | J16: EM | K16: EM - PEDIDO (013492) ITEM +(0005) / (ASSISTENCIA MEDICA | M16: 000055 | N16: 000000 | O16: 4.905,00 | P16: 0,00 | Q16: 0,00 | R16: 0,00 | S16: 0,00 | V16: 302 | W16: 11 | Z16: 010101
A17: =VLOOKUP(F17,'Contas Orç'!A:B,2,0) -> BENEFICIOS | B17: =VLOOKUP(C17,Base_20.12!E:E,1,0) -> 0000000007 | C17: 0000000007 | D17: 0006 | E17: 44879 | F17: 320103 | G17: 304 | H17: 21 | I17: Credito | J17: EM | K17: EM - PEDIDO (013492) ITEM +(0006) / (ASSISTENCIA MEDICA | M17: 000055 | N17: 000000 | O17: 11.568,00 | P17: 0,00 | Q17: 0,00 | R17: 0,00 | S17: 0,00 | V17: 304 | W17: 21 | Z17: 010101
A18: =VLOOKUP(F18,'Contas Orç'!A:B,2,0) -> BENEFICIOS | B18: =VLOOKUP(C18,Base_20.12!E:E,1,0) -> 0000000007 | C18: 0000000007 | D18: 0007 | E18: 44879 | F18: 320103 | G18: 305 | H18: 33 | I18: Credito | J18: EM | K18: EM - PEDIDO (013492) ITEM +(0007) / (ASSISTENCIA MEDICA | M18: 000055 | N18: 000000 | O18: 608,00 | P18: 0,00 | Q18: 0,00 | R18: 0,00 | S18: 0,00 | V18: 305 | W18: 33 | Z18: 010101
A19: =VLOOKUP(F19,'Contas Orç'!A:B,2,0) -> BENEFICIOS | B19: =VLOOKUP(C19,Base_20.12!E:E,1,0) -> 0000000007 | C19: 0000000007 | D19: 0008 | E19: 44879 | F19: 330103 | G19: 206 | H19: 90 | I19: Credito | J19: EM | K19: EM - PEDIDO (013492) ITEM +(0008) / (ASSISTENCIA MEDICA | M19: 000055 | N19: 000000 | O19: 563,00 | P19: 0,00 | Q19: 0,00 | R19: 0,00 | S19: 0,00 | V19: 206 | W19: 90 | Z19: 010101
A20: =VLOOKUP(F20,'Contas Orç'!A:B,2,0) -> BENEFICIOS | B20: =VLOOKUP(C20,Base_20.12!E:E,1,0) -> 0000000007 | C20: 0000000007 | D20: 0009 | E20: 44879 | F20: 320103 | G20: 301 | H20: 90 | I20: Credito | J20: EM | K20: EM - PEDIDO (013492) ITEM +(0009) / (ASSISTENCIA MEDICA | M20: 000055 | N20: 000000 | O20: 704,00 | P20: 0,00 | Q20: 0,00 | R20: 0,00 | S20: 0,00 | V20: 301 | W20: 90 | Z20: 010101
A21: =VLOOKUP(F21,'Contas Orç'!A:B,2,0) -> BENEFICIOS | B21: =VLOOKUP(C21,Base_20.12!E:E,1,0) -> 0000000007 | C21: 0000000007 | D21: 0010 | E21: 44879 | F21: 320103 | G21: 303 | H21: 31 | I21: Credito | J21: EM | K21: EM - PEDIDO (013492) ITEM +(0010) / (ASSISTENCIA MEDICA | M21: 000055 | N21: 000000 | O21: 11.421,00 | P21: 0,00 | Q21: 0,00 | R21: 0,00 | S21: 0,00 | V21: 303 | W21: 31 | Z21: 010101
A22: =VLOOKUP(F22,'Contas Orç'!A:B,2,0) -> BENEFICIOS | B22: =VLOOKUP(C22,Base_20.12!E:E,1,0) -> 0000000007 | C22: 0000000007 | D22: 0011 | E22: 44879 | F22: 320103 | G22: 305 | H22: 90 | I22: Credito | J22: EM | K22: EM - PEDIDO (013492) ITEM +(0011) / (ASSISTENCIA MEDICA | M22: 000055 | N22: 000000 | O22: 71.588,00 | P22: 0,00 | Q22: 0,00 | R22: 0,00 | S22: 0,00 | V22: 305 | W22: 90 | Z22: 010101
... A114: =VLOOKUP(F114,'Contas Orç'!A:B,2,0) -> PJ-OUTROS SERVICOS CONTRATADOS-PJ | B114: =VLOOKUP(C114,Base_20.12!E:E,1,0) -> 0000000025 | C114: 0000000025 | D114: 0002 | E114: 44879 | F114: 330201006 | G114: 211 | H114: 51 | I114: Debito | J114: EM | K114: EM - PED (013494) PROD: (23010001) / FOR: (ROYAL CONSTRUCOES | M114: 000054 | N114: 000132 | O114: 33.809,00 | P114: 0,00 | Q114: 0,00 | R114: 0,00 | S114: 0,00 | V114: 211 | W114: 51 | Z114: 010101
A115: =VLOOKUP(F115,'Contas Orç'!A:B,2,0) -> #N/A | B115: =VLOOKUP(C115,Base_20.12!E:E,1,0) -> 0000000026 | C115: 0000000026 | D115: 0001 | E115: 44882 | G115: 305 | H115: 21 | I115: Credito | J115: EM | K115: EM - PED (013495) PROD: (42010009) / FOR: (HYSTER YALE BRASI | M115: 000055 | N115: 000000 | O115: 170.000,00 | P115: 0,00 | Q115: 0,00 | R115: 0,00 | S115: 0,00 | V115: 305 | W115: 21 | Z115: 010101
A116: =VLOOKUP(F116,'Contas Orç'!A:B,2,0) -> #N/A | B116: =VLOOKUP(C116,Base_20.12!E:E,1,0) -> 0000000026 | C116: 0000000026 | D116: 0002 | E116: 44882 | G116: 305 | H116: 21 | I116: Credito | J116: EM | K116: EM - PED (013495) PROD: (42010008) / FOR: (HYSTER YALE BRASI | M116: 000055 | N116: 000000 | O116: 172.000,00 | P116: 0,00 | Q116: 0,00 | R116: 0,00 | S116: 0,00 | V116: 305 | W116: 21 | Z116: 010101
A117: =VLOOKUP(F117,'Contas Orç'!A:B,2,0) -> COMBUSTIVEIS | B117: =VLOOKUP(C117,Base_20.12!E:E,1,0) -> 0000000027 | C117: 0000000027 | D117: 0001 | E117: 44882 | F117: 330301001 | G117: 209 | H117: 11 | I117: Credito | J117: EM | K117: EM - PED (013496) PROD: (11100008) / FOR: (PETROTUDO COMERCI | M117: 000055 | N117: 000000 | O117: 64.090,00 | P117: 0,00 | Q117: 0,00 | R117: 0,00 | S117: 0,00 | V117: 209 | W117: 11 | Z117: 010101
A118: =VLOOKUP(F118,'Contas Orç'!A:B,2,0) -> COMBUSTIVEIS | B118: =VLOOKUP(C118,Base_20.12!E:E,1,0) -> 0000000027 | C118: 0000000027 | D118: 0002 | E118: 44882 | F118: 330301001 | G118: 209 | H118: 21 | I118: Credito | J118: EM | K118: EM - PED (013496) PROD: (11100008) / FOR: (PETROTUDO COMERCI | M118: 000055 | N118: 000000 | O118: 64.090,00 | P118: 0,00 | Q118: 0,00 | R118: 0,00 | S118: 0,00 | V118: 209 | W118: 21 | Z118: 010101
A119: =VLOOKUP(F119,'Contas Orç'!A:B,2,0) -> PECAS E ACESSORIOS | B119: =VLOOKUP(C119,Base_20.12!E:E,1,0) -> 0000000028 | C119: 0000000028 | D119: 0001 | E119: 44882 | F119: 320301004 | G119: 304 | H119: 11 | I119: Credito | J119: EM | K119: EM - PED (013500) PROD: (22010002) / FOR: (FREIO DIESEL PECA | M119: 000055 | N119: 000000 | O119: 398,00 | P119: 0,00 | Q119: 0,00 | R119: 0,00 | S119: 0,00 | V119: 304 | W119: 11 | Z119: 010101
A120: =VLOOKUP(F120,'Contas Orç'!A:B,2,0) -> PJ-OUTROS SERVICOS CONTRATADOS-PJ | B120: =VLOOKUP(C120,Base_20.12!E:E,1,0) -> 0000000029 | C120: 0000000029 | D120: 0001 | E120: 44882 | F120: 330201006 | G120: 201 | H120: 90 | I120: Credito | J120: EM | K120: EM - PED (013499) PROD: (23010016) / FOR: (APROVADOR SISTEMA | M120: 000055 | N120: 000000 | O120: 499,00 | P120: 0,00 | Q120: 0,00 | R120: 0,00 | S120: 0,00 | V120: 201 | W120: 90 | Z120: 010101
A121: =VLOOKUP(F121,'Contas Orç'!A:B,2,0) -> PJ-OUTROS SERVICOS CONTRATADOS-PJ | B121: =VLOOKUP(C121,Base_20.12!E:E,1,0) -> 0000000029 | C121: 0000000029 | D121: 0002 | E121: 44882 | F121: 330201006 | G121: 201 | H121: 90 | I121: Credito | J121: EM | K121: EM - PED (013499) PROD: (23010016) / FOR: (APROVADOR SISTEMA | M121: 000055 | N121: 000000 | O121: 499,00 | P121: 0,00 | Q121: 0,00 | R121: 0,00 | S121: 0,00 | V121: 201 | W121: 90 | Z121: 010101
A122: =VLOOKUP(F122,'Contas Orç'!A:B,2,0) -> PJ-OUTROS SERVICOS CONTRATADOS-PJ | B122: =VLOOKUP(C122,Base_20.12!E:E,1,0) -> 0000000029 | C122: 0000000029 | D122: 0003 | E122: 44882 | F122: 330201006 | G122: 201 | H122: 90 | I122: Credito | J122: EM | K122: EM - PED (013499) PROD: (23010016) / FOR: (APROVADOR SISTEMA | M122: 000055 | N122: 000000 | O122: 499,00 | P122: 0,00 | Q122: 0,00 | R122: 0,00 | S122: 0,00 | V122: 201 | W122: 90 | Z122: 010101
A123: =VLOOKUP(F123,'Contas Orç'!A:B,2,0) -> PJ-OUTROS SERVICOS CONTRATADOS-PJ | B123: =VLOOKUP(C123,Base_20.12!E:E,1,0) -> 0000000029 | C123: 0000000029 | D123: 0004 | E123: 44882 | F123: 330201006 | G123: 201 | H123: 90 | I123: Credito | J123: EM | K123: EM - PED (013499) PROD: (23010016) / FOR: (APROVADOR SISTEMA | M123: 000055 | N123: 000000 | O123: 499,00 | P123: 0,00 | Q123: 0,00 | R123: 0,00 | S123: 0,00 | V123: 201 | W123: 90 | Z123: 010101
A124: =VLOOKUP(F124,'Contas Orç'!A:B,2,0) -> PJ-OUTROS SERVICOS CONTRATADOS-PJ | B124: =VLOOKUP(C124,Base_20.12!E:E,1,0) -> 0000000029 | C124: 0000000029 | D124: 0005 | E124: 44882 | F124: 330201006 | G124: 201 | H124: 90 | I124: Credito | J124: EM | K124: EM - PED (013499) PROD: (23010016) / FOR: (APROVADOR SISTEMA | M124: 000055 | N124: 000000 | O124: 499,00 | P124: 0,00 | Q124: 0,00 | R124: 0,00 | S124: 0,00 | V124: 201 | W124: 90 | Z124: 010101
A125: =VLOOKUP(F125,'Contas Orç'!A:B,2,0) -> PJ-OUTROS SERVICOS CONTRATADOS-PJ | B125: =VLOOKUP(C125,Base_20.12!E:E,1,0) -> 0000000029 | C125: 0000000029 | D125: 0006 | E125: 44882 | F125: 330201006 | G125: 201 | H125: 90 | I125: Credito | J125: EM | K125: EM - PED (013499) PROD: (23010016) / FOR: (APROVADOR SISTEMA | M125: 000055 | N125: 000000 | O125: 499,00 | P125: 0,00 | Q125: 0,00 | R125: 0,00 | S125: 0,00 | V125: 201 | W125: 90 | Z125: 010101
A126: =VLOOKUP(F126,'Contas Orç'!A:B,2,0) -> PJ-LOCACAO DE MAQUINAS E EQUIPAMENTO | B126: =VLOOKUP(C126,Base_20.12!E:E,1,0) -> 0000000030 | C126: 0000000030 | D126: 0001 | E126: 44882 | F126: 320201004 | G126: 301 | H126: 90 | I126: Credito | J126: EM | K126: EM - PED (013498) PROD: (23010005) / FOR: (COMPANHIA DE LOCA | M126: 000055 | N126: 000000 | O126: 3.631,00 | P126: 0,00 | Q126: 0,00 | R126: 0,00 | S126: 0,00 | V126: 301 | W126: 90 | Z126: 010101
A127: =VLOOKUP(F127,'Contas Orç'!A:B,2,0) -> PJ-LOCACAO DE MAQUINAS E EQUIPAMENTO | B127: =VLOOKUP(C127,Base_20.12!E:E,1,0) -> 0000000030 | C127: 0000000030 | D127: 0002 | E127: 44882 | F127: 320201004 | G127: 301 | H127: 90 | I127: Credito | J127: EM | K127: EM - PED (013498) PROD: (23010005) / FOR: (COMPANHIA DE LOCA | M127: 000055 | N127: 000000 | O127: 3.701,00 | P127: 0,00 | Q127: 0,00 | R127: 0,00 | S127: 0,00 | V127: 301 | W127: 90 | Z127: 010101
A128: =VLOOKUP(F128,'Contas Orç'!A:B,2,0) -> PJ-LOCACAO DE MAQUINAS E EQUIPAMENTO | B128: =VLOOKUP(C128,Base_20.12!E:E,1,0) -> 0000000030 | C128: 0000000030 | D128: 0003 | E128: 44882 | F128: 320201004 | G128: 301 | H128: 90 | I128: Credito | J128: EM | K128: EM - PED (013498) PROD: (23010005) / FOR: (COMPANHIA DE LOCA | M128: 000055 | N128: 000000 | O128: 1.885,00 | P128: 0,00 | Q128: 0,00 | R128: 0,00 | S128: 0,00 | V128: 301 | W128: 90 | Z128: 010101
... A260: =VLOOKUP(F260,'Contas Orç'!A:B,2,0) -> PJ-OUTROS SERVICOS CONTRATADOS-PJ | B260: =VLOOKUP(C260,Base_20.12!E:E,1,0) -> 0000000077 | C260: 0000000077 | D260: 0002 | E260: 44886 | F260: 330201006 | G260: 201 | H260: 90 | I260: Debito | J260: EM | K260: EM - PED (013507) PROD: (23010006) / FOR: (BERNUTTY TECHNOLO | M260: 000054 | N260: 000070 | O260: 586,34 | P260: 0,00 | Q260: 0,00 | R260: 0,00 | S260: 0,00 | V260: 201 | W260: 90 | Z260: 010101
A261: =VLOOKUP(F261,'Contas Orç'!A:B,2,0) -> RECEITA BRUTA DE TRANSPORTES | B261: =VLOOKUP(C261,Base_20.12!E:E,1,0) -> 0000000078 | C261: 0000000078 | D261: 0001 | E261: 44888 | F261: 310101 | G261: 304 | H261: 11 | I261: Credito | J261: RE | K261: RE - NF (000053700) P: (21010001) C: (HAMBURG SUD A/S) | M261: 000101 | N261: 000132 | O261: 1.582,57 | P261: 0,00 | Q261: 0,00 | R261: 0,00 | S261: 0,00 | T261: ORC2022_2 | V261: 304 | W261: 11 | Z261: 010101
A262: =VLOOKUP(F262,'Contas Orç'!A:B,2,0) -> IMOBILIZADO EM ANDAMENTO - PROPRIOS | B262: =VLOOKUP(C262,Base_20.12!E:E,1,0) -> 0000000079 | C262: 0000000079 | D262: 0001 | E262: 44888 | F262: 120307001 | G262: 211 | H262: 51 | I262: Credito | J262: EM | K262: EM - PED (013508) PROD: (11100029) / FOR: (POSTO PECEM COMER | M262: 000055 | N262: 000000 | O262: 241,77 | P262: 0,00 | Q262: 0,00 | R262: 0,00 | S262: 0,00 | T262: ORC2022_2 | V262: 211 | W262: 51 | Z262: 010101
...

Sheet Planilha1
A2: COMPETÊNCIA | B2: 44866
A4: Soma de Valor | B4: Rótulos de Coluna
A5: Rótulos de Linha | B5: 0R | C5: EM | D5: RE | E5: SALDO
A6: 120302001 - MOVEIS E UTENSILIOS | B6: 0 | C6: 9.96 | D6: 5562.62 | E6: =B6-C6-D6 -> -5572.58
A7: 120307001 - IMOBILIZADO EM ANDAMENTO - PROPRIOS | B7: 0 | C7: 2.2737368e-12 | D7: 24610.18 | E7: =B7-C7-D7 -> -24610.18
A8: 310101 - RECEITA BRUTA DE TRANSPORTES | B8: 1550796.5 | C8: 0 | D8: 101736.94 | E8: =B8-C8-D8 -> 1449059.5
A9: 310102 - RECEITA BRUTA DE OPERACOES PORTUARIAS | B9: 11333539 | C9: 0 | D9: 0 | E9: =B9-C9-D9 -> 11333539
A10: 310109 - ( - ) DEDUCOES DA RECEITA BRUTA | B10: 1968645.2 | C10: 0 | D10: 0 | E10: =B10-C10-D10 -> 1968645.2
A11: 310901 - OUTRAS RECEITAS | B11: 217883.2 | C11: 0 | D11: 52.95 | E11: =B11-C11-D11 -> 217830.25
A12: 320101 - REMUNERACOES | B12: 1516567.3 | C12: 0 | D12: -9.99 | E12: =B12-C12-D12 -> 1516577.3
A13: 320102 - ENCARGOS SOCIAIS | B13: 254000.43 | C13: 0 | D13: 0 | E13: =B13-C13-D13 -> 254000.43
A14: 320103 - BENEFICIOS | B14: 391504.25 | C14: 0 | D14: -106245.57 | E14: =B14-C14-D14 -> 497749.82
A15: 320104 - OUTROS GASTOS COM PESSOAL | B15: 43720.33 | C15: 0 | D15: 0 | E15: =B15-C15-D15 -> 43720.33
A16: 320201001 - PJ-CONSULTORIA E ASSESSORIA | B16: 22613.09 | C16: 0 | D16: 0 | E16: =B16-C16-D16 -> 22613.09
A17: 320201004 - PJ-LOCACAO DE MAQUINAS E EQUIPAMENTO | B17: 462494.14 | C17: 14849.38 | D17: 29694.62 | E17: =B17-C17-D17 -> 417950.14
... A70: Total Geral | B70: 26401932 | C70: 113616.36 | D70: 372227.4 | E70: =B70-C70-D70 -> 25916088

Sheet Stênio
A1: COMPETÊNCIA | B1: 44866
A3: Soma de Valor | B3: Rótulos de Coluna
A4: Rótulos de Linha | B4: 0R | C4: EM | D4: RE
A5: 120302001 - MOVEIS E UTENSILIOS | B5: 0 | C5: 9.96 | D5: 5562.62
A6: 120307001 - IMOBILIZADO EM ANDAMENTO - PROPRIOS | B6: 0 | C6: 2.2737368e-12 | D6: 24610.18
A7: 310101 - RECEITA BRUTA DE TRANSPORTES | B7: 1550796.5 | C7: 0 | D7: 101736.94
A8: 310102 - RECEITA BRUTA DE OPERACOES PORTUARIAS | B8: 11333539 | C8: 0 | D8: 0
A9: 310109 - ( - ) DEDUCOES DA RECEITA BRUTA | B9: 1968645.2 | C9: 0 | D9: 0
A10: 310901 - OUTRAS RECEITAS | B10: 217883.2 | C10: 0 | D10: 52.95
A11: 320101 - REMUNERACOES | B11: 1516567.3 | C11: 0 | D11: -9.99
A12: 320102 - ENCARGOS SOCIAIS | B12: 254000.43 | C12: 0 | D12: 0
A13: 320103 - BENEFICIOS | B13: 391504.25 | C13: 0 | D13: -106245.57
A14: 320104 - OUTROS GASTOS COM PESSOAL | B14: 43720.33 | C14: 0 | D14: 0
A15: 320201001 - PJ-CONSULTORIA E ASSESSORIA | B15: 22613.09 | C15: 0 | D15: 0
A16: 320201004 - PJ-LOCACAO DE MAQUINAS E EQUIPAMENTO | B16: 462494.14 | C16: 14849.38 | D16: 29694.62
... A73: 380201 - DESPESAS FINANCEIRAS | B73: 1098369.9 | C73: 0 | D73: 2.99
